2025-06-26 06:19:19,169 INFO    MainThread:3841146 [wandb_setup.py:_flush():81] Current SDK version is 0.20.1
2025-06-26 06:19:19,169 INFO    MainThread:3841146 [wandb_setup.py:_flush():81] Configure stats pid to 3841146
2025-06-26 06:19:19,169 INFO    MainThread:3841146 [wandb_setup.py:_flush():81] Loading settings from /home2/yanghaochen/.config/wandb/settings
2025-06-26 06:19:19,169 INFO    MainThread:3841146 [wandb_setup.py:_flush():81] Loading settings from /home2/yanghaochen/MoE_franka/wandb/settings
2025-06-26 06:19:19,169 INFO    MainThread:3841146 [wandb_setup.py:_flush():81] Loading settings from environment variables
2025-06-26 06:19:19,169 INFO    MainThread:3841146 [wandb_init.py:setup_run_log_directory():703] Logging user logs to /home2/yanghaochen/MoE_franka/wandb/run-20250626_061919-so1csmel/logs/debug.log
2025-06-26 06:19:19,169 INFO    MainThread:3841146 [wandb_init.py:setup_run_log_directory():704] Logging internal logs to /home2/yanghaochen/MoE_franka/wandb/run-20250626_061919-so1csmel/logs/debug-internal.log
2025-06-26 06:19:19,169 INFO    MainThread:3841146 [wandb_init.py:init():831] calling init triggers
2025-06-26 06:19:19,169 INFO    MainThread:3841146 [wandb_init.py:init():836] wandb.init called with sweep_config: {}
config: {'name': 'MoE-KGC-Franka', 'hidden_dim': 768, 'num_experts': 5, 'expert_hidden_dim': 512, 'num_heads': 12, 'dropout_rate': 0.1, 'activation': 'gelu', 'experts': {'action_expert': ExpertConfig(hidden_dims=[512, 256], use_attention=True, dropout_rate=0.1), 'spatial_expert': ExpertConfig(hidden_dims=[512, 256], use_attention=True, dropout_rate=0.1), 'temporal_expert': ExpertConfig(hidden_dims=[512, 256], use_attention=True, dropout_rate=0.1), 'semantic_expert': ExpertConfig(hidden_dims=[512, 256], use_attention=True, dropout_rate=0.1), 'safety_expert': ExpertConfig(hidden_dims=[512, 256], use_attention=True, dropout_rate=0.1)}, 'gating': GatingConfig(temperature=1.0, noise_std=0.1, top_k=2, load_balancing_weight=0.01), 'graph': GraphConfig(num_layers=3, aggregation='mean', use_edge_features=True, edge_hidden_dim=128), 'training': TrainingConfig(batch_size=32, learning_rate=0.0001, weight_decay='1e-5', epochs=100, gradient_clip=1.0, warmup_steps=1000, scheduler='cosine'), 'data': DataConfig(max_seq_length=512, vocab_size=30522, num_relations=50, num_entity_types=20), 'franka': FrankaConfig(joint_dim=7, gripper_dim=2, force_torque_dim=6, workspace_bounds={'x': [-0.855, 0.855], 'y': [-0.855, 0.855], 'z': [0.0, 1.19]}), 'paths': {'data_dir': './data/raw_data', 'processed_dir': './data/processed', 'model_dir': './checkpoints', 'log_dir': './logs'}, 'evaluation': {'metrics': ['accuracy', 'f1', 'mrr', 'hits@k'], 'k_values': [1, 3, 10], 'save_predictions': True}, '_wandb': {}}
2025-06-26 06:19:19,169 INFO    MainThread:3841146 [wandb_init.py:init():872] starting backend
2025-06-26 06:19:19,389 INFO    MainThread:3841146 [wandb_init.py:init():875] sending inform_init request
2025-06-26 06:19:19,397 INFO    MainThread:3841146 [wandb_init.py:init():883] backend started and connected
2025-06-26 06:19:19,403 INFO    MainThread:3841146 [wandb_init.py:init():956] updated telemetry
2025-06-26 06:19:19,407 INFO    MainThread:3841146 [wandb_init.py:init():980] communicating run to backend with 90.0 second timeout
2025-06-26 06:19:50,369 INFO    Thread-1 (wrapped_target):3841146 [retry.py:__call__():173] [no run ID] Retry attempt failed:
Traceback (most recent call last):
  File "/home2/yanghaochen/anaconda3/envs/franka/lib/python3.12/site-packages/urllib3/connection.py", line 198, in _new_conn
    sock = connection.create_connection(
           ^^^^^^^^^^^^^^^^^^^^^^^^^^^^^
  File "/home2/yanghaochen/anaconda3/envs/franka/lib/python3.12/site-packages/urllib3/util/connection.py", line 85, in create_connection
    raise err
  File "/home2/yanghaochen/anaconda3/envs/franka/lib/python3.12/site-packages/urllib3/util/connection.py", line 73, in create_connection
    sock.connect(sa)
TimeoutError: timed out

The above exception was the direct cause of the following exception:

Traceback (most recent call last):
  File "/home2/yanghaochen/anaconda3/envs/franka/lib/python3.12/site-packages/urllib3/connectionpool.py", line 787, in urlopen
    response = self._make_request(
               ^^^^^^^^^^^^^^^^^^^
  File "/home2/yanghaochen/anaconda3/envs/franka/lib/python3.12/site-packages/urllib3/connectionpool.py", line 488, in _make_request
    raise new_e
  File "/home2/yanghaochen/anaconda3/envs/franka/lib/python3.12/site-packages/urllib3/connectionpool.py", line 464, in _make_request
    self._validate_conn(conn)
  File "/home2/yanghaochen/anaconda3/envs/franka/lib/python3.12/site-packages/urllib3/connectionpool.py", line 1093, in _validate_conn
    conn.connect()
  File "/home2/yanghaochen/anaconda3/envs/franka/lib/python3.12/site-packages/urllib3/connection.py", line 753, in connect
    self.sock = sock = self._new_conn()
                       ^^^^^^^^^^^^^^^^
  File "/home2/yanghaochen/anaconda3/envs/franka/lib/python3.12/site-packages/urllib3/connection.py", line 207, in _new_conn
    raise ConnectTimeoutError(
urllib3.exceptions.ConnectTimeoutError: (<urllib3.connection.HTTPSConnection object at 0x7f6cb2be0170>, 'Connection to api.wandb.ai timed out. (connect timeout=20)')

The above exception was the direct cause of the following exception:

Traceback (most recent call last):
  File "/home2/yanghaochen/anaconda3/envs/franka/lib/python3.12/site-packages/requests/adapters.py", line 667, in send
    resp = conn.urlopen(
           ^^^^^^^^^^^^^
  File "/home2/yanghaochen/anaconda3/envs/franka/lib/python3.12/site-packages/urllib3/connectionpool.py", line 841, in urlopen
    retries = retries.increment(
              ^^^^^^^^^^^^^^^^^^
  File "/home2/yanghaochen/anaconda3/envs/franka/lib/python3.12/site-packages/urllib3/util/retry.py", line 519, in increment
    raise MaxRetryError(_pool, url, reason) from reason  # type: ignore[arg-type]
    ^^^^^^^^^^^^^^^^^^^^^^^^^^^^^^^^^^^^^^^^^^^^^^^^^^^
urllib3.exceptions.MaxRetryError: HTTPSConnectionPool(host='api.wandb.ai', port=443): Max retries exceeded with url: /graphql (Caused by ConnectTimeoutError(<urllib3.connection.HTTPSConnection object at 0x7f6cb2be0170>, 'Connection to api.wandb.ai timed out. (connect timeout=20)'))

During handling of the above exception, another exception occurred:

Traceback (most recent call last):
  File "/home2/yanghaochen/anaconda3/envs/franka/lib/python3.12/site-packages/wandb/sdk/lib/retry.py", line 134, in __call__
    result = self._call_fn(*args, **kwargs)
             ^^^^^^^^^^^^^^^^^^^^^^^^^^^^^^
  File "/home2/yanghaochen/anaconda3/envs/franka/lib/python3.12/site-packages/wandb/sdk/internal/internal_api.py", line 396, in execute
    return self.client.execute(*args, **kwargs)  # type: ignore
           ^^^^^^^^^^^^^^^^^^^^^^^^^^^^^^^^^^^^
  File "/home2/yanghaochen/anaconda3/envs/franka/lib/python3.12/site-packages/wandb/vendor/gql-0.2.0/wandb_gql/client.py", line 52, in execute
    result = self._get_result(document, *args, **kwargs)
             ^^^^^^^^^^^^^^^^^^^^^^^^^^^^^^^^^^^^^^^^^^^
  File "/home2/yanghaochen/anaconda3/envs/franka/lib/python3.12/site-packages/wandb/vendor/gql-0.2.0/wandb_gql/client.py", line 60, in _get_result
    return self.transport.execute(document, *args, **kwargs)
           ^^^^^^^^^^^^^^^^^^^^^^^^^^^^^^^^^^^^^^^^^^^^^^^^^
  File "/home2/yanghaochen/anaconda3/envs/franka/lib/python3.12/site-packages/wandb/sdk/lib/gql_request.py", line 58, in execute
    request = self.session.post(self.url, **post_args)
              ^^^^^^^^^^^^^^^^^^^^^^^^^^^^^^^^^^^^^^^^
  File "/home2/yanghaochen/anaconda3/envs/franka/lib/python3.12/site-packages/requests/sessions.py", line 637, in post
    return self.request("POST", url, data=data, json=json, **kwargs)
           ^^^^^^^^^^^^^^^^^^^^^^^^^^^^^^^^^^^^^^^^^^^^^^^^^^^^^^^^^
  File "/home2/yanghaochen/anaconda3/envs/franka/lib/python3.12/site-packages/requests/sessions.py", line 589, in request
    resp = self.send(prep, **send_kwargs)
           ^^^^^^^^^^^^^^^^^^^^^^^^^^^^^^
  File "/home2/yanghaochen/anaconda3/envs/franka/lib/python3.12/site-packages/requests/sessions.py", line 703, in send
    r = adapter.send(request, **kwargs)
        ^^^^^^^^^^^^^^^^^^^^^^^^^^^^^^^
  File "/home2/yanghaochen/anaconda3/envs/franka/lib/python3.12/site-packages/requests/adapters.py", line 688, in send
    raise ConnectTimeout(e, request=request)
requests.exceptions.ConnectTimeout: HTTPSConnectionPool(host='api.wandb.ai', port=443): Max retries exceeded with url: /graphql (Caused by ConnectTimeoutError(<urllib3.connection.HTTPSConnection object at 0x7f6cb2be0170>, 'Connection to api.wandb.ai timed out. (connect timeout=20)'))
